Workbook

Sheet Autocall
B1: SE0006993184 | C1: FI4000053178 | D1: SE0006261947 | E1: SE0006993192 | F1: XS1311310384 | G1: XS1322968394 | H1: SE0004575314 | I1: FI4000149547 | J1: XS1311310384 | K1: SE0005366390 | L1: FI4000177118 | M1: SE0005506029 | N1: SE0008587455
B2: 100/80/60 flat | C2: 100/80/60 memory | D2: 100/100/60 memory | E2: 100/100/60 | F2: 100/100 flat Capital Protected | G2: 100/80/60 flat coupon paid at call | H2: 100/100/60 memory | I2: 100/100/150 memory | J2: 100/100 memory Capital Protected | K2: 100/60/60 memory on call, flat on coupon barrier | L2: 100/80/60 memory | M2: 100/60/60 memory | N2: 100/100/60 flat
B3: Autocall 1 | C3: Autocall 2 | D3: Autocall 3 | E3: Autocall 4 | F3: Autocall 5 | G3: Autocall 6 | H3: Autocall 7 | I3: Autocall 8 | J3: Autocall 9 | K3: Autocall 10 | L3: Autocall 11 | M3: Autocall 12 | N3: Autocall 13
A4: Level 1 | B4: Autocall | C4: Autocall | D4: Autocall | E4: Autocall | F4: Autocall | G4: Autocall | H4: Autocall | I4: Autocall | J4: Autocall | K4: Autocall | L4: Autocall | M4: Autocall | N4: Autocall
A5: Level 2 | B5: Worst of | C5: Worst of | D5: Worst of | E5: Worst of | F5: Worst of | G5: Worst of | H5: Single underlying | I5: Single underlying FX | J5: Worst of | K5: Worst of | L5: Single underlying | M5: Worst of | N5: Worst of
A6: Level 3 | B6: Flat coupon | C6: Memory coupon | D6: Classic autocall | E6: Two coupons | F6: Flat coupon | G6: Flat coupon, accrued and paid on call or maturity | H6: Classic autocall | I6: Memory coupon | J6: Memory coupon | K6: Two coupons | L6: Memory coupon | M6: Memory coupon | N6: Flat coupon
A7: Level 4 | D7: Memory coupon | F7: Capital guaranteed | H7: Memory coupon | J7: Capital guaranteed
A8: Short description | B8: This is an autocallable with more than one underlying asset. It has a call barrier and a coupon barrier, which are at different levels, and a risk barrier. The coupon is flat, no memory. | C8: This is an autocallable with more than one underlying asset. It has a call barrier and a coupon barrier at different levels, and a risk barrier. The coupon is a memory coupon. | D8: This is an autocallable with more than one underlying asset. It has a call barrier and a coupon barrier, which are at the same level, and a risk barrier. The coupon is a memory coupon. | E8: This is an autocallable with more than one underlying asset. It has a call barrier and a coupon barrier, which are at the same level, and a risk barrier. There are two coupons, one guaranteed and one call coupon. | F8: This is a capital protected autocallable with more than one underlying asset. It has a call barrier and a coupon barrier with the same level. The coupon is flat, no memory. | G8: This is an autocallable with more than one underlying asset. It has a call barrier and a coupon barrier at different levels, and a risk barrier. The coupon(s) will be accrued and paid at call. | H8: This is an autocallable with one underlying asset. It has a call barrier and a coupon barrier at the same level, and a risk barrier. The coupon is a memory coupon. | I8: This is an autocallable with one underlying asset (currency pair). It has a call barrier and a coupon barrier at the same level, and a risk barrier on a higher level. The coupon is a memory coupon. | J8: This is a capital protected autocallable with more than one underlying asset. It has a call barrier and a coupon barrier at the same level. The coupon is a memory coupon. | K8: This is an autocallable with more than one underlying asset. It has a call barrier and a coupon barrier at different levels, and a risk barrier. There are two coupons, one flat coupon paid when the worst performing underlying asset is at or above the coupon barrier, but below the call barrier. And one memory coupon (call coupon) paid when all underlying assets are at or above the call barrier. | L8: This is an autocallable with one underlying asset. It has a call barrier and a coupon barrier on different levels, and a risk barrier. The coupon is a memory coupon. | M8: This is an autocallable with more than one underlying asset. It has a call barrier and a coupon barrier at different levels, and a risk barrier. The coupon is a memory coupon. | N8: This is an autocallable with more than one underlying asset. It has a call barrier and a coupon barrier, which are at the same level, and a risk barrier. The coupon is a flat coupon.
A9: EUSIPA-code | B9: 1260 | C9: 1260 | D9: 1260 | E9: 1260 | F9: 1260 | G9: 1260 | H9: 1260 | I9: 1260 | J9: 1260 | K9: 1260 | L9: 1260 | M9: 1260 | N9: 1260
A10: JIRA Code
A11: JIRA Issue ID
A12: JIRA Product Feature | B12: EDIP | C12: EDIP | D12: EDIP | E12: EDIP | F12: 100%CapProtected | G12: EDIP | H12: EDIP | I12: EDIP | J12: 100%CapProtected | K12: EDIP | L12: EDIP | M12: EDIP | N12: EDIP
A13: JIRA Product Feature | B13: DigitalObs | C13: DigitalObs Memory | D13: DigitalObs Memory | E13: DigitalObs Zero | F13: DigitalObs Coupon | G13: DigitalObs CouponAccrued | H13: DigitalObs Memory | I13: DigitalObs Memory | J13: DigitalObs Coupon | K13: DigitalObs Coupon | L13: DigitalObs Memory | M13: DigitalObs Memory | N13: DigitalObs Coupon
A14: JIRA Product Feature | B14: CallObs Zero | C14: CallObs Zero | D14: CallObs Zero | E14: CallObs Coupon | F14: CallObs Zero | G14: CallObs Zero | H14: CallObs Zero | I14: CallObs Zero | J14: CallObs Zero | K14: CallObs xN | L14: CallObs Zero | M14: CallObs Zero | N14: CallObs Zero
A15: JIRA Product Feature | E15: FixedCoupons | G15: Special
A16: Fixing needed? | B16: FinalFixing, DigitalObsFixing, CallObsFixing | C16: FinalFixing, DigitalObsFixing, CallObsFixing | D16: FinalFixing, DigitalObsFixing, CallObsFixing | E16: FinalFixing, DigitalObsFixing, CallObsFixing | F16: FinalFixing, DigitalObsFixing, CallObsFixing | G16: FinalFixing, DigitalObsFixing, CallObsFixing | H16: FinalFixing, DigitalObsFixing, CallObsFixing | I16: FinalFixing, DigitalObsFixing, CallObsFixing | J16: FinalFixing, DigitalObsFixing, CallObsFixing | K16: FinalFixing, DigitalObsFixing, CallObsFixing | L16: FinalFixing, DigitalObsFixing, CallObsFixing | M16: FinalFixing, DigitalObsFixing, CallObsFixing | N16: FinalFixing, DigitalObsFixing, CallObsFixing
A19: Type | B19: Express certificate (Autocall) 1 b according to the MiFID (legal form?) | C19: Express certificate (Autocall) 1 b according to the MiFID (legal form?) | D19: Express certificate (Autocall) 1 b according to the MiFID (legal form?) | E19: Express certificate (Autocall) 1 b according to the MiFID (legal form?) | F19: Express certificate (Autocall) 1 b according to the MiFID (legal form?) | G19: Express certificate (Autocall) 1 b according to the MiFID (legal form?) | H19: Express certificate (Autocall) 1 b according to the MiFID (legal form?) | I19: Express certificate (Autocall) 1 b according to the MiFID (legal form?) | J19: Express certificate (Autocall) 1 b according to the MiFID (legal form?) | K19: Express certificate (Autocall) 1 b according to the MiFID (legal form?) | L19: Express certificate (Autocall) 1 b according to the MiFID (legal form?) | M19: Express certificate (Autocall) 1 b according to the MiFID (legal form?) | N19: Express certificate (Autocall) 1 b according to the MiFID (legal form?)
B20: Underlying asset(s) (initial price) | C20: Underlying asset(s) (initial price) | D20: Underlying asset(s) (initial price) | E20: Underlying asset(s) (initial price) | F20: Underlying asset(s) (initial price) | G20: Underlying asset(s) (initial price) | H20: Underlying asset(s) (initial price) | I20: Underlying asset(s) (initial price) | J20: Underlying asset(s) (initial price) | K20: Underlying asset(s) (initial price) | L20: Underlying asset(s) (initial price) | M20: Underlying asset(s) (initial price) | N20: Underlying asset(s) (initial price)
A21: How the investment works | B21: The objective is to receive a coupon, even if the worst performing underlying asset remains unchanged or even has a slightly negative performance. | C21: The objective is to receive a coupon, even if the worst performing underlying asset remains unchanged or even has a slightly negative performance. | D21: The objective is to receive a coupon, even if the worst performing underlying asset remains unchanged or even has a slightly negative performance. | E21: The objective is to receive a coupon, even if the worst performing underlying asset remains unchanged or even has a slightly negative performance. | F21: The objective is to receive a coupon, even if the worst performing underlying asset remains unchanged or even has a slightly negative performance. | G21: The objective is to receive a coupon, even if the worst performing underlying asset remains unchanged or even has a slightly negative performance. | H21: The objective is to receive a coupon, even if the underlying asset remains unchanged or even has a slightly negative performance. | I21: The objective is to receive a coupon, even if the underlying asset remains unchanged or even has a slightly positive performance. | J21: The objective is to receive a coupon, even if the worst performing underlying asset remains unchanged or even has a slightly negative performance. | K21: The objective is to receive a coupon, even if the worst performing underlying asset remains unchanged or even has a slightly negative performance. | L21: The objective is to receive a coupon, even if the underlying asset remains unchanged or even has a slightly negative performance. | M21: The objective is to receive a coupon, even if the worst performing underlying asset remains unchanged or even has a slightly negative performance. | N21: The objective is to receive a coupon, even if the worst performing underlying asset remains unchanged or even has a slightly negative performance.
B22: The return of the investment depends on the performance of the worst performing underlying asset during the lifetime of the investment. | C22: The return of the investment depends on the performance of the worst performing underlying asset during the lifetime of the investment. | D22: The return of the investment depends on the performance of the worst performing underlying asset during the lifetime of the investment. | E22: The return of the investment depends on the performance of the worst performing underlying asset during the lifetime of the investment. | F22: The return of the investment depends on the performance of the worst performing underlying asset during the lifetime of the investment. | G22: The return of the investment depends on the performance of the worst performing underlying asset during the lifetime of the investment. | H22: The return of the investment depends on the performance of the underlying asset during the lifetime of the investment. | I22: The return of the investment depends on the performance of the underlying asset during the lifetime of the investment. | J22: The return of the investment depends on the performance of the worst performing underlying asset during the lifetime of the investment. | K22: The return of the investment depends on the performance of the worst performing underlying asset during the lifetime of the investment. | L22: The return of the investment depends on the performance of the underlying asset during the lifetime of the investment. | M22: The return of the investment depends on the performance of the worst performing underlying asset during the lifetime of the investment. | N22: The return of the investment depends on the performance of the worst performing underlying asset during the lifetime of the investment.
B23: If, on an observation date, all underlying assets are at or above the call barrier the note will redeem early and the nominal amount plus a coupon will be paid on the early redemption date immediately following the observation date. | C23: If, on an observation date, all underlying assets are at or above the call barrier the note will redeem early and the nominal amount plus a coupon for each observation date that has passed and not previously paid any coupon will be paid on the early redemption date immediately following the observation date. | D23: If, on an observation date, all underlying assets are at or above the call barrier and the coupon barrier the note will redeem early and the nominal amount plus a coupon for each observation date that has passed will be paid on the early redemption date immediately following the observation date. | E23: If, on an observation date, all underlying assets are at or above the call barrier and the coupon barrier the note will redeem early and the nominal amount, the guaranteed coupon and a call coupon will be paid on the early redemption date immediately following the observation date. | F23: If, on an observation date, all underlying assets are at or above the call barrier and the coupon barrier the note will redeem early and the nominal amount plus a coupon will be paid on the early redemption date immediately following the observation date. | G23: If, on an observation date, all underlying assets are at or above the call barrier the note will redeem early and the nominal amount plus a coupon for each valuation date that has passed where all underlying assets has been at or above the coupon barrier, will be paid on the early redemption date immediately following the observation date. | H23: If, on an observation date, the underlying asset is at or above the call barrier and the coupon barrier the note will redeem early and the nominal amount plus a coupon for each observation date that has passed will be paid on the early redemption date immediately following the observation date. | I23: If, on an observation date, the underlying asset is at or below the call barrier and the coupon barrier the note will redeem early and the nominal amount plus a coupon for each observation date that has passed will be paid on the early redemption date immediately following the observation date. | J23: If, on an observation date, all underlying assets are at or above the call barrier and the coupon barrier the note will redeem early and the nominal amount plus a coupon for each observation date that has passed will be paid on the early redemption date immediately following the observation date. | K23: If, on an observation date, all underlying assets are at or above the call barrier the note will redeem early and the nominal amount plus a call coupon for each observation date that has passed will be paid on the early redemption date immediately following the observation date. | L23: If, on an observation date, the underlying asset is at or above the call barrier the note will redeem early and the nominal amount plus a coupon for each observation date that has passed and not previously paid any coupon will be paid on the early redemption date immediately following the observation date. | M23: If, on an observation date, all underlying assets are at or above the call barrier the note will redeem early and the nominal amount plus a coupon for each observation date that has passed and not previously paid any coupon will be paid on the early redemption date immediately following the observation date. | N23: If, on an observation date, all underlying assets are at or above the call barrier and the coupon barrier the note will redeem early and the nominal amount plus a coupon will be paid on the early redemption date immediately following the observation date.
B24: If, on a valuation date, the worst performing underlying asset is at or above the coupon barrier, but below the call barrier, a coupon will be paid on the next interest payment date. The note will not redeem and the maturity will extend at least to the next early redemption date. | C24: If, on a valuation date, the worst performing underlying asset is at or above the coupon barrier, but below the call barrier, a coupon for each valuation date that has passed and not previously paid any coupon will be paid on the next interest payment date. The note will not redeem and the maturity will extend at least to the next early redemption date. | D24: If, on a observation date, the worst performing underlying asset is below the call barrier and the coupon barrier, the note will not redeem and the maturity will extend at least to the next early redemption date. | E24: If, on an observation date, the worst performing underlying asset is below the call barrier and the coupon barrier the note will pay the guaranteed coupon. The note will not redeem and the maturity will extend at least to the next early redemption date. | F24: If, on an observation date, the worst performing underlying asset is below the call barrier and the coupon barrier the note will not redeem and the maturity will extend at least to the next early redemption date without paying any coupon. | G24: If, on a valuation date, the worst performing underlying asset is at or above the coupon barrier, but below the call barrier, a coupon will be recorded. The coupon will be paid when the note is redeemed, at the redemption date at the latest. | H24: If, on an observation date, the underlying asset is below the call barrier and the coupon barrier the note will not redeem and the maturity will extend at least to the next early redemption date. | I24: If, on an observation date, the underlying asset is above the call barrier and the coupon barrier the note will not redeem and the maturity will extend at least to the next early redemption date. | J24: If, on an observation date, the worst performing underlying asset is below the call barrier and the coupon barrier the note will not redeem and the maturity will extend at least to the next early redemption date. | K24: If, on a valuation date, the worst performing underlying asset is at or above the coupon barrier, but below the call barrier, the note will pay a flat coupon. The note will not redeem and the maturity will extend at least to the next early redemption date. | L24: If, on a valuation date, the underlying asset is at or above the coupon barrier, but below the call barrier, a coupon for each valuation date that has passed and not previously paid any coupon will be paid on the next interest payment date. The note will not redeem and the maturity will extend at least to the next early redemption date. | M24: If, on a valuation date, the worst performing underlying asset is at or above the coupon barrier, but below the call barrier, a coupon for each valuation date that has passed and not previously paid any coupon will be paid on the next interest payment date. The note will not redeem and the maturity will extend at least to the next early redemption date. | N24: If, on a observation date, the worst performing underlying asset is below the call barrier and the coupon barrier, the note will not redeem and the maturity will extend at least to the next early redemption date.
B25: If, on a valuation date, the worst performing underlying asset is below both the call barrier and the coupon barrier, the note will not redeem and the maturity will extend at least to the next early redemption date without paying any coupon. | C25: If, on a valuation date, the worst performing underlying asset is below both the call barrier and the coupon barrier, the note will not redeem and the maturity will extend at least to the next early redemption date. | D25: On the last observation date there are three possible scenarios: 1. All underlying assets are at or above the call barrier and the coupon barrier. The note will then pay the nominal amount plus a coupon for each observation date that has passed, on the redemption date. 2. The worst performing underlying asset is below the call barrier and the coupon barrier, but at or above the risk barrier. The note will then pay the nominal amount on the redemption date. 3. The worst performing underlying asset is below the risk barrier. The note will then pay the nominal amount reduced by the negative performance of the worst performing underlying asset, on the redemption date. | E25: On the last observation date there are three possible scenarios: 1. All underlying assets are at or above the call barrier and the coupon barrier. The note will then pay the nominal amount, the guaranteed coupon and a call coupon on the redemption date. 2. The worst performing underlying asset is below the call barrier and the coupon barrier, but at or above the risk barrier. The note will then pay the nominal amount and the guaranteed coupon on the redemption date. 3. The worst performing underlying asset is below the risk barrier. The note will then pay the nominal amount, reduced by the negative performance of the worst performing underlying asset, and the guaranteed coupon on the redemption date. | F25: On the last observation date there are two possible scenarios: 1. All underlying assets are at or above the coupon barrier and the call barrier. The note will then pay the nominal amount plus a coupon on the redemption date. 2. The worst performing underlying asset has a negative performance. The note will then pay the nominal amount on the redemption date. | G25: If, on a valuation date, the worst performing underlying asset is below both the call barrier and the coupon barrier, no coupon will be credited. | H25: On the last observation date there are three possible scenarios: 1. The underlying asset is at or above the call barrier and the coupon barrier. The note will then pay the nominal amount plus a coupon for each observation date that has passed and not previously paid any coupon on the redemption date. 2. The underlying asset is below the call barrier and the coupon barrier, but at or above the risk barrier. The note will then pay the nominal amount on the redemption date. 3. The underlying asset is below the risk barrier. The note will then pay the nominal amount reduced by the negative performance of the underlying asset, on the redemption date. | I25: If, on the last observation date, the underlying asset is above the risk barrier the note will pay less than the nominal amount. | J25: On the last observation date there are two possible scenarios: 1. All underlying assets are at or above the coupon barrier and the call barrier. The note will then pay the nominal amount plus a coupon for each observation date that has passed on the redemption date. 2. The worst performing underlying asset has a negative performance. The note will then pay the nominal amount on the redemption date. | K25: If, on a valuation date, the worst performing underlying asset is below both the call barrier and the coupon barrier, the note will not redeem and the maturity will extend at least to the next early redemption date without paying any flat coupon. | L25: If, on a valuation date, the underlying asset is below both the call barrier and the coupon barrier, the note will not redeem and the maturity will extend at least to the next early redemption date. | M25: If, on a valuation date, the worst performing underlying asset is below both the call barrier and the coupon barrier, the note will not redeem and the maturity will extend at least to the next early redemption date. | N25: On the last observation date there are three possible scenarios: 1. All underlying assets are at or above the call barrier and the coupon barrier. The note will then pay the nominal amount plus a coupon on the redemption date. 2. The worst performing underlying asset is below the call barrier and the coupon barrier, but at or above the risk barrier. The note will then pay the nominal amount on the redemption date. 3. The worst performing underlying asset is below the risk barrier. The note will then pay the nominal amount reduced by the negative performance of the worst performing underlying asset, on the redemption date.
B26: On the last observation date there are three possible scenarios: 1. All underlying assets are at or above the coupon barrier. The note will then pay the nominal amount plus a coupon on the redemption date. 2. The worst performing underlying asset is below the coupon barrier, but at or above the risk barrier. The note will then pay the nominal amount on the redemption date. 3. The worst performing underlying asset is below the risk barrier. The note will then pay the nominal amount reduced by the negative performance of the worst performing underlying asset, on the redemption date. | C26: On the last observation date there are three possible scenarios: 1. All underlying assets are at or above the coupon barrier. The note will then pay the nominal amount plus a coupon for each observation dvaluation date that has passed and not previously paid any coupon, on the redemption date. 2. The worst performing underlying asset is below the coupon barrier, but at or above the risk barrier. The note will then pay the nominal amount on the redemption date. 3. The worst performing underlying asset is below the risk barrier. The note will then pay the nominal amount reduced by the negative performance of the worst performing underlying asset, on the redemption date. | G26: On the last observation date there are three possible scenarios: 1. All underlying assets are at or above the coupon barrier. The note will then pay the nominal amount plus a coupon for the last period and for each valuation date that has passed where all underlying assets has been at or above the coupon barrier, on the redemption date. 2. The worst performing underlying asset is below the coupon barrier, but at or above the risk barrier. The note will then pay the nominal amount plus a coupon for each valuation date that has passed where all underlying assets has been at or above the coupon barrier, on the redemption date. 3. The worst performing underlying asset is below the risk barrier. The note will then pay the nominal amount, reduced by the negative performance of the worst performing underlying asset, plus a coupon for each valuation date that has passed where all underlying assets has been at or above the coupon barrier, on the redemption date. | K26: On the last observation date there are three possible scenarios: 1. All underlying assets are at or above the call barrier. The note will then pay the nominal amount plus a call coupon for each observation date that has passed, on the redemption date. 2. The worst performing underlying asset is below the call barrier, but at or above the coupon barrier. The note will then pay the nominal amount plus a flat coupon on the redemption date. 3. The worst performing underlying asset is below the risk barrier. The note will then pay the nominal amount reduced by the negative performance of the worst performing underlying asset on the redemption date. | L26: On the last observation date there are three possible scenarios: 1. The underlying asset is at or above the coupon barrier. The note will then pay the nominal amount plus a coupon for each observation date that has passed and not previously paid any coupon on the redemption date. 2. The underlying asset is below the coupon barrier, but at or above the risk barrier. The note will then pay the nominal amount on the redemption date. 3. The underlying asset is below the risk barrier. The note will then pay the nominal amount reduced by the negative performance of the underlying asset on the redemption date. | M26: On the last observation date there are two possible scenarios: 1. All underlying assets are at or above the risk barrier. The note will then pay the nominal amount plus a coupon for each observation date that has passed and not previously paid any coupon, on the redemption date. 2. The worst performing underlying asset is below the risk barrier. The note will then pay the nominal amount reduced by the negative performance of the worst performing underlying asset on the redemption date.
A28: Key numbers:
B29: Minimum subscription amount | C29: Minimum subscription amount | D29: Minimum subscription amount | E29: Minimum subscription amount | F29: Minimum subscription amount | G29: Minimum subscription amount | H29: Minimum subscription amount | I29: Minimum subscription amount | J29: Minimum subscription amount | K29: Minimum subscription amount | L29: Minimum subscription amount | M29: Minimum subscription amount | N29: Minimum subscription amount
B30: Subscription end date | C30: Subscription end date | D30: Subscription end date | E30: Subscription end date | F30: Subscription end date | G30: Subscription end date | H30: Subscription end date | I30: Subscription end date | J30: Subscription end date | K30: Subscription end date | L30: Subscription end date | M30: Subscription end date | N30: Subscription end date
B31: Issue price | C31: Issue price | D31: Issue price | E31: Issue price | F31: Issue price | G31: Issue price | H31: Issue price | I31: Issue price | J31: Issue price | K31: Issue price | L31: Issue price | M31: Issue price | N31: Issue price
B32: Issue date | C32: Issue date | D32: Issue date | E32: Issue date | F32: Issue date | G32: Issue date | H32: Issue date | I32: Issue date | J32: Issue date | K32: Issue date | L32: Issue date | M32: Issue date | N32: Issue date
B33: Nominal amount + currency | C33: Nominal amount + currency | D33: Nominal amount + currency | E33: Nominal amount + currency | F33: Nominal amount/Capital protection + currency | G33: Nominal amount + currency | H33: Nominal amount + currency | I33: Nominal amount + currency | J33: Nominal amount/Capital protection + currency | K33: Nominal amount + currency | L33: Nominal amount + currency | M33: Nominal amount + currency | N33: Nominal amount + currency
B34: Coupon | C34: Coupon | D34: Coupon | E34: Guaranteed coupon | F34: Coupon | G34: Coupon | H34: Coupon | I34: Coupon | J34: Coupon | K34: Call coupon | L34: Coupon | M34: Coupon | N34: Coupon
B35: Call barrier | C35: Call barrier | D35: Call barrier | E35: Call coupon | F35: Call barrier | G35: Call barrier | H35: Call barrier | I35: Call barrier | J35: Call barrier | K35: Flat coupon | L35: Call barrier | M35: Call barrier | N35: Call barrier
B36: Coupon barrier | C36: Coupon barrier | D36: Coupon barrier | E36: Coupon barrier | F36: Coupon barrier | G36: Coupon barrier | H36: Coupon barrier | I36: Coupon barrier | J36: Coupon barrier | K36: Call barrier | L36: Coupon barrier | M36: Coupon barrier | N36: Coupon barrier
B37: Risk barrier | C37: Risk barrier | D37: Risk barrier | E37: Call barrier | F37: Observation date(s) | G37: Risk barrier | H37: Risk barrier | I37: Risk barrier | J37: Observation date(s) | K37: Coupon barrier | L37: Risk barrier | M37: Risk barrier | N37: Risk barrier
B38: Observation date(s) | C38: Observation date(s) | D38: Observation date(s) | E38: Risk barrier | F38: Early redemption date(s) | G38: Observation date(s) | H38: Observation date(s) | I38: Observation date(s) | J38: Early redemption date(s) | K38: Risk barrier | L38: Observation date(s) | M38: Observation date(s) | N38: Observation date(s)
B39: Valuation date(s) | C39: Valuation date(s) | D39: Early redemption date(s) | E39: Observation date(s) | F39: Redemption date | G39: Valuation date(s) | H39: Early redemption date(s) | I39: Early redemption date(s) | J39: Redemption date | K39: Observation date(s) | L39: Valuation date(s) | M39: Valuation date(s) | N39: Early redemption date(s)
B40: Early redemption date(s) | C40: Early redemption date(s) | D40: Redemption date | E40: Early redemption date(s) | G40: Early redemption date(s) | H40: Redemption date | I40: Redemption date | K40: Valuation date(s) | L40: Early redemption date(s) | M40: Early redemption date(s) | N40: Redemption date
B41: Interest payment date(s) | C41: Interest payment date(s) | E41: Redemption date | G41: Redemption date | K41: Early redemption date(s) | L41: Interest payment date(s) | M41: Interest payment date(s)
B42: Redemption date | C42: Redemption date | I42: Initial valuation date | J42: Initial valuation date | K42: Redemption date | L42: Redemption date | M42: Redemption date
D43: Initial valuation date | E43: Initial valuation date | F43: Initial valuation date | G43: Initial valuation date | H43: Initial valuation date | N43: Initial valuation date
...

Sheet Capital protected
B1: SE0006261657 | C1: SE0006992608 | D1: SE0006261970 | E1: FI4000090683 | F1: FI4000040530 | G1: SE0005472099 | H1: SE0005130960 | I1: SE0004391241 KP 45, bäst av tre | J1: SE0007665450 | K1: SE0005506136 | M1: DK0030344965 | N1: NONE OUTSTANDING - REMOVE | O1: FI4000069919 | P1: SE0005796281 - KP71 | R1: FI4000041280 | S1: DK0030334495 | T1: FI4000040522 | U1: FI4000040365 | V1: SE0004548204 | W1: DK0030297197 | X1: SE0004724904 | Y1: DK0030317722 | Z1: SE0006992400 | AA1: DK0030302377 | AB1: SE0005795861 | AD1: SE0005505906 | AE1: SE0004491066 | AF1: SE0005126232 | AG1: XS1344758468 | AH1: XS1241177390 | AI1: SE0006262291 | AJ1: SE0005224227 | AK1: FI4000033949 | AL1: FI4000040381 | AM1: FI4000041694 | AN1: FI4000046289 | AO1: REMOVE | AP1: REMOVE
B2: Capital protected 1 | C2: Capital protected 2 | D2: Capital protected 3 | E2: Capital protected 4 | F2: Capital protected 5 | G2: Capital protected 6 | H2: Capital protected 7 | I2: Capital protected 8 | J2: Capital protected 9 | K2: Capital protected 10 | L2: Capital protected 11 | M2: Capital protected 12 | N2: Capital protected 13 | O2: Capital protected 14 | P2: Capital protected 15 | Q2: Capital protected 16 | R2: Capital protected 17 | S2: Capital protected 18 | T2: Capital protected 19 | U2: Capital protected 20 | V2: Capital protected 21 | W2: Capital protected 22 | X2: Capital protected 23 | Y2: Capital protected 24 | Z2: Capital protected 26 | AA2: Capital protected 27 | AB2: Capital protected 28 | AC2: Capital protected 29 | AD2: Capital protected 30 | AE2: Capital protected 31 | AF2: Capital protected 32 | AG2: Capital protected 33 | AH2: Capital protected 34 | AI2: Capital protected 35 | AJ2: Capital protected 36 | AK2: Capital protected 37 | AL2: Capital protected 38 | AM2: Capital protected 39 | AN2: Capital protected 40 | AO2: Capital protected 41 | AP2: Capital protected 42
A3: Level 1 | B3: Multi underlying | C3: Multi underlying | D3: Multi underlying with best replacement | E3: Multi underlying with best replacement | F3: Multi underlying | G3: Multi underlying | H3: Single underlying | I3: Multi underlying, best performance | J3: Multi underlying with best replacement structure | K3: Single underlying, TOM | L3: Single underlying, TOM | M3: Multi underlying, underlying performance is the difference between performance in two different underlying assets | N3: Single underlying, TOM | O3: Multi underlying FX | P3: Multi underlying FX | Q3: Multi underlying | R3: Single underlying (rate) | S3: Multi underlying, relative difference betweeen two assets | T3: Single underlying (interest rate) | U3: Single underlying (interest rate) | V3: Single underlying (interest rate) | W3: Single underlying | X3: Multi underlying (relative difference between two underlying assets) | Y3: Multi underlying (relative difference between two underlying assets) | Z3: Single underlying | AA3: Single underlying | AB3: Single underlying | AC3: Single underlying | AD3: Multi underlying | AE3: Multi underlying, TOM | AF3: Single underlying, monthly performance | AG3: Multi underlying (relative difference between two underlying assets) | AH3: Multi underlying (relative difference between two underlying assets) | AI3: Multi underlying FX | AJ3: Single underlying | AK3: Single underlying (interest rate) | AL3: Single underlying (rate) | AM3: Single underlying (interest rate) | AN3: Single underlying (interest rate) | AO3: Multi underlying with best replacement | AP3: Multi underlying (relative difference between two underlying assets)
A4: Level 2 | B4: Participation ratio | C4: Participation ratio | D4: Participation ratio | E4: Participation ratio | F4: Participation ratio | G4: Capped coupon | H4: Participation ratio | I4: Participation ratio | J4: Participation ratio | K4: Participation ratio | L4: Participation ratio | M4: Participation ratio | N4: Participation ratio | O4: Participation ratio | P4: Participation ratio | Q4: Participation ratio | R4: Interest, accrued and paid at redemption | S4: Participation ratio | T4: Fixed interest rate. Accrued, acumulated and paid at redemption | U4: Floating interest | V4: Floating interest | W4: Fixed coupon | X4: Fixed coupon for a set number of interest payment dates | Y4: Participation ratio | Z4: Participation ratio | AA4: Participation ratio | AB4: Participation ratio | AC4: Participation ratio | AD4: Participation ratio | AE4: Participation ratio | AF4: Capped (monthly) + lock-in | AG4: Fixed interest for a set number of interest payment dates | AH4: Floating interest | AI4: Participation ratio | AJ4: Participation ratio | AK4: Floating interest | AL4: Interest, accrued and paid at redemption | AM4: Floating interest | AN4: Fixed interest for a set number of interest payment dates | AO4: Participation ratio | AP4: Fixed interest for a set number of interest payment dates
A5: Level 3 | B5: Flexo | C5: Quanto | D5: Flexo | E5: Quanto | F5: Capped | G5: Quanto | H5: Quanto | I5: Quanto | J5: Quanto | K5: Flexo | M5: Quanto | N5: Capped (monthly) + lock-in | O5: Quanto | P5: Best of | Q5: Capped on basket level | R5: Floor and cap | S5: Floor and cap | U5: Cap | V5: Floor and cap | W5: Floor and cap | X5: Floating interest for the forthcoming interest payment dates | Y5: Fixed interest | Z5: Flexo | AA5: Fixed coupon(Guaranteed, paid on each interest payment date) | AB5: Fixed coupon(Guaranteed) paid at maturity | AC5: Fixed coupon(Guaranteed) paid at maturity | AD5: Fixed coupon(Guaranteed) paid on each interest payment date | AE5: Quanto | AF5: Quanto | AG5: Floating interest for the forthcoming interest payment dates | AH5: Floor and cap - CMS spread | AI5: Rainbow | AJ5: Fixed coupon(Guaranteed, paid on each interest payment date) | AK5: Floor and cap | AL5: Cap | AM5: Floor and cap | AN5: Floating interest for the forthcoming interest payment dates | AO5: Quanto | AP5: Floating interest for the forthcoming interest payment dates
A6: Level 4 | F6: Quanto | L6: Quanto | N6: Quanto | P6: Quanto | Q6: Quanto | Y6: Floor and cap - CMS spread | AA6: Flexo | AB6: Flexo | AC6: Quanto | AD6: Quanto | AG6: Floor and cap - CMS spread | AI6: Quanto | AJ6: Quanto | AN6: Floor and cap | AP6: Barrier
A7: Short description | B7: This is a capital protected note with more than one underlying asset in a basket. The note is affected by currency fluctuations. | C7: This is a capital protected note with more than one underlying asset in a basket. | D7: This is a capital protected note with more than one underlying asset in a basket. When calculating the basket performance, a specified number of the best performing underlying assets in the basket will be given a fixed performance each. The note is affected by currency fluctuations. | E7: This is a capital protected note with more than one underlying asset in a basket. When calculating the basket performance, a specified number of the best performing underlying assets in the basket will be given a fixed performance each. | F7: This is a capital protected note with more than one underlying asset in a basket. When calculating the basket performance, each underlying asset has a cap. | G7: This is a capital protected note with a basket of underlying assets. If the underlying basket has a positive performance a coupon will be paid. There is a cap on the coupon. | H7: This is a capital protected note with one underlying asset. | I7: This is a capital protected note with more than one underlying asset in different baskets. At maturity the calculated returns for all the baskets is ranked. The best performer is then applied in order to calculate the return. | J7: This is a capital protected note with more than one underlying asset in a basket. When calculating the basket performance, a specified number of the best performing underlying assets in the basket will be given a fixed performance each. For a specific basket performance range, the note will pay the nominal amount plus the nominal amount multiplied by a fixed predefined coupon. For any basket performance above that range, the note will pay the nominal amount plus the nominal amount multiplied by the performance of the basket multiplied by the participation ratio on the redemption date. | K7: This is a capital protected note with one underlying asset. The performance of the underlying asset is determined by a predefined strategy – turn of the month. Turn of the month means that the note is exposed to the underlying asset only during a predefined number of days per month. The note is affected by currency fluctuations. | L7: This is a capital protected note with one underlying asset. The performance of the underlying asset is determined by a predefined strategy – turn of the month. Turn of the month means that the note is exposed to the underlying asset only during a predefined number of days per month. | M7: This is a capital protected note with more than one underlying asset. The performance of the underlying asset is determined by calculating the difference in the return between two different underlying assets. | N7: This is a capital protected note with one underlying asset. The performance of the underlying asset is determined by a predefined strategy – turn of the month. Turn of the month means that the note is exposed to the underlying asset only during a predefined number of days per month. Each monthly performance is capped at a predefined level. If the sum of the monthly performances exceeds a predefined lock-in level, the minimum redemption price at maturity is increased to that level. | O7: This is a capital protected note with more than one underlying asset (currency pairs = basket short) in a basket. | P7: This is a capital protected note with more than one underlying currency pairs. At maturity the calculated returns for all the underlying baskets (currency pairs) is ranked. The best performer is then applied in order to calculate the return. | Q7: This is a capital protected note with more than one underlying asset in a basket. When calculating the basket performance, the performance of the underlying basket has a cap. | R7: This is a capital protected note linked to a reference rate. The note pays a floating interest rate, which has a floor and cap for each year. The interest rate is accumulated, meaning that the amount on which the interest is calculated is increasing with each interest rate period. On the redemption date, the note pays the nominal amount plus any accumulated interest rates. | S7: This is a capital protected note, linked to the relative difference between two underlying interest rates. The interest rate spread has a floor and a cap. On the redemption date, the note will pay the nominal amount + nominal amount x the relative difference (taking into account the floor and the cap) x participation ratio. | T7: This is a capital protected note with a fixed interest rate. The interest rate is accumulated, meaning that the amount on which the interest is calculated is increasing with each interest rate period. On the redemption date, the note pays the nominal amount plus accumulated interest rate. | U7: This is a capital protected note linked to a floating reference rate. The note pays a reference rate + interest margin, calculated on the nominal amount on each interest payment date. The annual interest rate has a cap. On the redemption date, the note pays the nominal amount. | V7: This is a capital protected note linked to a floating reference rate. If, on an interest determination date, the reference rate is within a predefined interval, the note will pay the reference rate plus the interest margin multiplied by the nominal amount on the next interest payment date. If the reference rate is lower than the floor, or higher than the cap, the note will pay the reference rate multiplied by the nominal amount on the next interest payment date. On the redemption date, the note pays the nominal amount. | W7: This is a capital protected note with one underlying asset. If, on a valuation date, the underlying asset is within a predefined interval, the note will be credited a predefined coupon. If, on a valuation date, the underlying asset is lower or higher than the predefined interval, no coupon will be credited for that period. The coupon is accumulated and paid on each interest payment date. On the redemption date, the note will pay nominal amount. | X7: This is a capital protected note linked to the relative difference between two underlying assets. The note will pay a fixed coupon for a set number of interest payment dates, calculated on the nominal amount. For the forthcoming interest payment dates, the note will pay a floating interest payment. On the redemption date, the note will pay the nominal amount. | Y7: This is a capital protected note, linked to the relative difference between two underlying interest rates. The interest rate spread has a floor and a cap. On the redemption date, the note will pay the nominal amount + nominal amount x the relative difference (taking into account the floor and the cap) x participation ratio. On each interest payment date, the note will pay a fixed interest, calculated on the nominal amount. | Z7: This is a capital protected note with one underlying asset. The note is affected by currency fluctuations. | AA7: This is a capital protected note with one underlying asset. The note pays a fixed guaranteed coupon, on each interest payment date, calculated on the nominal amount. The note is affected by currency fluctuations. | AB7: This is a capital protected note with one underlying asset. The note pays a fixed guaranteed coupon at maturity, calculated on the nominal amount. The note is affected by currency fluctuations. | AC7: This is a capital protected note with one underlying asset. The note pays a fixed guaranteed interest at maturity, calculated on the nominal amount. | AD7: This is a capital protected note with more than one underlying asset. The note pays a fixed guaranteed interest, on each interest payment date, calculated on the nominal amount. | AE7: This is a capital protected note with more than one underlying asset. The performance of the underlying assets is determined by a predefined strategy – turn of the month. Turn of the month means that the note is exposed to the underlying assets only during a predefined number of days per month. | AF7: This is a capital protected note with one underlying asset. Each monthly performance is capped at a predefined level. If the sum of the monthly performances exceeds a predefined lock-in level, the minimum redemption amount at maturity is increased to that level. | AG7: This is a capital protected note linked to the relative difference between two underlying assets. The note will pay a fixed coupon for a set number of interest payment dates, calculated on the nominal amount. For the forthcoming interest payment dates, the note will pay a floating coupon, linked to an interest rate spread. The interest rate spread has a floor and a cap. On the redemption date, the note will pay the nominal amount. | AH7: This is a capital protected note linked to the relative difference between two underlying assets. The note will pay a floating coupon, linked to an interest rate spread. The interest rate spread has a floor and a cap. On the redemption date, the note will pay the nominal amount. | AI7: This is a capital protected note with more than one underlying currency pairs. If the basket has a positive performance, the note will pay the nominal amount plus the nominal amount multiplied by the performance of the basket multiplied by the participation ratio, on the redemption date. When calculating the basket performance, each currency pair will be given a speicific weight in the basket. If the basket has an negative performance, the note will pay the nominal amount on the redemption date. | AJ7: This is a capital protected note with one underlying asset. The note pays a fixed guaranteed coupon, on each interest payment date, calculated on the nominal amount. | AK7: This is a capital protected note linked to a floating reference rate. The note pays a floating reference rate, calculated on the nominal amount, on each interest payment date. The annual interest rate has a cap and a floor. On the redemption date, the note pays the nominal amount. | AL7: This is a capital protected note linked to a reference rate. The note pays a floating interest rate (reference rate + interest margin), which has a cap for each year, calculated on the nominal amount. The interest rate is accumulated, meaning that the amount on which the interest is calculated is increasing with each interest rate period. On the redemption date, the note pays the nominal amount plus accumulated interest rates. | AM7: This is a capital protected note linked to a floating reference rate. The note pays a floating reference rate (reference rate + interest margin), calculated on the nominal amount, on each interest payment date. The annual interest rate has a cap and a floor. On the redemption date, the note pays the nominal amount. | AN7: This is a capital protected note linked to a floating reference rate. The note will pay a fixed interest for a set number of interest payment dates, calculated on the nominal amount. For the forthcoming interest payment dates, the note will pay a floating interest (reference rate + interest margin) calculcated on the nominal amount. The floating interest payments has a yearly cap. | AO7: This is a capital protected note with more than one underlying asset in a basket. When calculating the basket performance, a specified number of the best performing underlying assets in the basket will be given a fixed performance each. | AP7: This is a capital protected note linked to the relative difference between two underlying assets. The note will pay a fixed coupon on the first interest payment date, calculated on the nominal amount. For the forthcoming interest payment dates, the note will pay a floating coupon, linked to the performance of an interest rate spread.
A8: EUSIPA-code | B8: 1100 | C8: 1100 | D8: 1100 | E8: 1100 | F8: 1120 | G8: 1120 | H8: 1100 | I8: 1100 | J8: 1100 | K8: 1100 | L8: 1100 | M8: 1100 | N8: 1140 | O8: 1100 | P8: 1100 | Q8: 1120 | R8: 1120 | S8: 1120 | T8: 1100 | U8: 1120 | V8: 1120 | W8: 1120 | X8: 1100 | Y8: 1120 | Z8: 1100 | AA8: 1100 | AB8: 1100 | AC8: 1100 | AD8: 1100 | AE8: 1100 | AF8: 1140 | AG8: 1120 | AH8: 1120 | AI8: 1100 | AJ8: 1100 | AO8: 1100 | AP8: 1120
B9: 100%CapitalProtection | C9: 100%CapitalProtection | D9: 100%CapitalProtection | E9: 100%CapitalProtection | F9: 100%CapitalProtection | G9: 100%CapitalProtection | H9: 100%CapitalProtection | I9: 100%CapitalProtection | J9: 100%CapitalProtection | K9: 100%CapitalProtection | L9: 100%CapitalProtection | M9: 100%CapitalProtection | N9: 100%CapitalProtection | O9: 100%CapitalProtection | P9: 100%CapitalProtection | Q9: 100%CapitalProtection | R9: 100%CapitalProtection | S9: 100%CapitalProtection | T9: 100%CapitalProtection | U9: 100%CapitalProtection | V9: 100%CapitalProtection | W9: 100%CapitalProtection | X9: 100%CapitalProtection | Y9: 100%CapitalProtection | Z9: 100%CapitalProtection | AA9: 100%CapitalProtection | AB9: 100%CapitalProtection | AC9: 100%CapitalProtection | AD9: 100%CapitalProtection | AE9: 100%CapitalProtection | AF9: 100%CapitalProtection | AG9: 100%CapitalProtection | AH9: 100%CapitalProtection | AI9: 100%CapitalProtection | AJ9: 100%CapitalProtection | AK9: 100%CapitalProtection | AL9: 100%CapitalProtection | AM9: 100%CapitalProtection | AN9: 100%CapitalProtection | AO9: 100%CapitalProtection | AP9: 100%CapitalProtection
B10: Call1 | C10: Call1 | D10: Special | E10: Special | F10: Call1 | G10: DigitalObs | H10: Call1 | I10: Call1 | J10: Best-of Coupon/Participation | K10: Special | L10: Special | M10: UnderlyingSpreadPerformance | N10: Special | R10: FloatingFixings | U10: FloatingFixings | V10: FloatingFixings | X10: FloatingFixings | Y10: FinalFixings | AG10: FloatingFixing | AH10: FloatingFixing | AK10: FloatingFixing | AL10: FloatingFixing | AM10: FloatingFixing | AN10: FloatingFixing
D11: UnderlyingSwitchToFixed | E11: UnderlyingSwitchToFixed | F11: IndividualCaps | G11: AsianObservation | J11: UnderlyingSwitchToFixed | K11: TOM | L11: TOM | N11: TOM
D12: BestReplacement | E12: BestReplacement | J12: BestReplacement
A13: Type | B13: 1 b according to the MiFID (legal form?) | C13: 1 b according to the MiFID (legal form?) | D13: 1 b according to the MiFID (legal form?) | E13: 1 b according to the MiFID (legal form?) | F13: 1 b according to the MiFID (legal form?) | G13: 1 b according to the MiFID (legal form?) | H13: 1 b according to the MiFID (legal form?) | I13: 1 b according to the MiFID (legal form?) | J13: 1 b according to the MiFID (legal form?) | K13: 1 b according to the MiFID (legal form?) | L13: 1 b according to the MiFID (legal form?) | M13: 1 b according to the MiFID (legal form?) | N13: 1 b according to the MiFID (legal form?) | O13: 1 b according to the MiFID (legal form?) | P13: 1 b according to the MiFID (legal form?) | Q13: 1 b according to the MiFID (legal form?) | R13: 1 b according to the MiFID (legal form?) | S13: 1 b according to the MiFID (legal form?) | T13: 1 b according to the MiFID (legal form?) | U13: 1 b according to the MiFID (legal form?) | V13: 1 b according to the MiFID (legal form?) | W13: 1 b according to the MiFID (legal form?) | X13: 1 b according to the MiFID (legal form?) | Y13: 1 b according to the MiFID (legal form?) | Z13: 1 b according to the MiFID (legal form?) | AA13: 1 b according to the MiFID (legal form?) | AB13: 1 b according to the MiFID (legal form?) | AC13: 1 b according to the MiFID (legal form?) | AD13: 1 b according to the MiFID (legal form?) | AE13: 1 b according to the MiFID (legal form?) | AF13: 1 b according to the MiFID (legal form?) | AG13: 1 b according to the MiFID (legal form?) | AH13: 1 b according to the MiFID (legal form?) | AI13: 1 b according to the MiFID (legal form?) | AJ13: 1 b according to the MiFID (legal form?) | AK13: 1 b according to the MiFID (legal form?) | AL13: 1 b according to the MiFID (legal form?) | AM13: 1 b according to the MiFID (legal form?) | AN13: 1 b according to the MiFID (legal form?) | AO13: 1 b according to the MiFID (legal form?) | AP13: 1 b according to the MiFID (legal form?)
B14: Uncapped Capital Protection | C14: Uncapped Capital Protection | D14: Uncapped Capital Protection | E14: Uncapped Capital Protection | F14: Capped Capital Protected | G14: Capped Capital Protected | H14: Uncapped Capital Protection | I14: Uncapped Capital Protection | J14: Uncapped Capital Protection | K14: Uncapped Capital Protection | L14: Uncapped Capital Protection | M14: Uncapped Capital Protection | N14: Capital Protection with Coupon | O14: Uncapped Capital Protection | P14: Uncapped Capital Protection | Q14: Capped Capital Protection | R14: Capped Capital Protection | S14: Capped Capital Protection | T14: Capped Capital Protection | U14: Capped Capital Protection | V14: Capped Capital Protection | W14: Capped Capital Protection | X14: Capped Capital Protection | Y14: Capped Capital Protection | Z14: Capped Capital Protection | AA14: Capped Capital Protection | AB14: Capped Capital Protection | AC14: Capped Capital Protection | AD14: Capped Capital Protection | AE14: Capped Capital Protection | AF14: Capped Capital Protection | AG14: Capped Capital Protection | AH14: Capped Capital Protection | AI14: Capped Capital Protection | AJ14: Capped Capital Protection | AK14: Capped Capital Protection | AO14: Uncapped Capital Protection | AP14: Capped Capital Protection
B15: Underlying asset(s) (initial price) | C15: Underlying asset(s) (initial price) | D15: Underlying asset(s) (initial price) | E15: Underlying asset(s) (initial price) | F15: Underlying asset(s) (initial price) | G15: Underlying asset(s) (initial price) | H15: Underlying asset(s) (initial price) | I15: Underlying asset(s) (initial price) | J15: Underlying asset(s) (initial price) | K15: Underlying asset(s) (initial price) | L15: Underlying asset(s) (initial price) | M15: Underlying asset(s) (initial price) | N15: Underlying asset(s) (initial price) | O15: Underlying asset(s) (initial price) | P15: Underlying asset(s) (initial price) | Q15: Underlying asset(s) (initial price) | R15: Underlying asset(s) | S15: Underlying asset(s) (initial price) | T15: Underlying asset(s) (initial price) | U15: Underlying asset(s) (initial price) | V15: Underlying asset(s) (initial price) | W15: Underlying asset(s) (initial price) | X15: Underlying asset(s) (initial price) | Y15: Underlying asset(s) (initial price) | Z15: Underlying asset(s) (initial price) | AA15: Underlying asset(s) (initial price) | AB15: Underlying asset(s) (initial price) | AC15: Underlying asset(s) (initial price) | AD15: Underlying asset(s) (initial price) | AE15: Underlying asset(s) (initial price) | AF15: Underlying asset(s) (initial price) | AG15: Underlying asset(s) (initial price) | AH15: Underlying asset(s) (initial price) | AI15: Underlying asset(s) (initial price) | AJ15: Underlying asset(s) (initial price) | AL15: Underlying asset(s) (initial price) | AM15: Underlying asset(s) (initial price) | AN15: Underlying asset(s) (initial price) | AO15: Underlying asset(s) (initial price) | AP15: Underlying asset(s) (initial price)
